<?xml version="1.0" ?>
<!-- =================================================================================== -->
<!-- |    This document was autogenerated by xacro from /home/fandes/workspace/kuavo-ros-control/src/humanoid-control/humanoid_interface_drake/models/biped_gen4.2/urdf/biped_v3.xacro | -->
<!-- |    EDITING THIS FILE BY HAND IS NOT RECOMMENDED                                 | -->
<!-- =================================================================================== -->
<robot name="biped_v3" xmlns:drake="https://drake.mit.edu">
  <link name="torso">
    <inertial>
      <origin rpy="0 0 0" xyz="-0.01779947 0.00029663 0.18176446"/>
      <mass value="33.83884316"/>
      <inertia ixx="0.84217451" ixy="-0.00019450" ixz="0.06746774" iyy="0.73769958" iyz="-0.00007935" izz="0.24371683"/>
    </inertial>
    <visual>
      <origin rpy="0 0 0" xyz="0 0 0"/>
      <geometry>
        <mesh filename="../../meshes/torso.STL"/>
      </geometry>
      <material name="">
        <color rgba="0.43137 0.45098 0.43137 1"/>
      </material>
    </visual>
    <!-- <collision>
      <origin xyz="0 0 0" rpy="0 0 0" />
      <geometry>
        <mesh filename="../../meshes/torso.STL" />
      </geometry>
    </collision> -->
  </link>
  <link name="l_leg_roll">
    <inertial>
      <origin rpy="0 0 0" xyz="-0.00430148 -0.00002708 -0.00851195"/>
      <mass value="1.71093115"/>
      <inertia ixx="0.00206092" ixy="-0.00000197" ixz="-0.00006944" iyy="0.00277274" iyz="0.00000510" izz="0.00370826"/>
    </inertial>
    <visual>
      <origin rpy="0 0 0" xyz="0 0 0"/>
      <geometry>
        <mesh filename="../../meshes/l_leg_roll.STL"/>
      </geometry>
      <material name="">
        <color rgba="0.6902 0.65882 0.63922 1"/>
      </material>
    </visual>
  </link>
  <joint name="l_leg_roll_joint" type="continuous">
    <origin rpy="0 0 0" xyz="-0.0024999 0.087 -0.066"/>
    <parent link="torso"/>
    <child link="l_leg_roll"/>
    <axis xyz="1 0 0"/>
    <limit effort="100" lower="-0.78" upper="1.57" velocity="25"/>
  </joint>
  <!--        ssss -->
  <transmission type="SimpleTransmission">
    <joint name="l_leg_roll_joint"/>
    <actuator name="l_leg_roll_motor"/>
  </transmission>
  <!-- sssssssss -->
  <link name="l_leg_yaw">
    <inertial>
      <origin rpy="0 0 0" xyz="0.00000000 -0.00322560 -0.09080869"/>
      <mass value="0.55762936"/>
      <inertia ixx="0.00213816" ixy="0.00000000" ixz="-0.00000003" iyy="0.00118284" iyz="0.00004162" izz="0.00139547"/>
    </inertial>
    <visual>
      <origin rpy="0 0 0" xyz="0 0 0"/>
      <geometry>
        <mesh filename="../../meshes/l_leg_yaw.STL"/>
      </geometry>
      <material name="">
        <color rgba="0.65098 0.61961 0.58824 1"/>
      </material>
    </visual>
  </link>
  <joint name="l_leg_yaw_joint" type="continuous">
    <origin rpy="0 0 0" xyz="0 0 0"/>
    <parent link="l_leg_roll"/>
    <child link="l_leg_yaw"/>
    <axis xyz="0 0 1"/>
    <limit effort="100" lower="-1.57" upper="1.57" velocity="25"/>
  </joint>
  <!--        ssss -->
  <transmission type="SimpleTransmission">
    <joint name="l_leg_yaw_joint"/>
    <actuator name="l_leg_yaw_motor"/>
  </transmission>
  <!-- sssssssss -->
  <link name="l_leg_pitch">
    <inertial>
      <origin rpy="0 0 0" xyz="0.00185677 0.01023458 -0.08558380"/>
      <mass value="4.43577451"/>
      <inertia ixx="0.04271209" ixy="-0.00000777" ixz="-0.00143032" iyy="0.04341831" iyz="-0.00092942" izz="0.01102339"/>
    </inertial>
    <visual>
      <origin rpy="0 0 0" xyz="0 0 0"/>
      <geometry>
        <mesh filename="../../meshes/l_leg_pitch.STL"/>
      </geometry>
      <material name="">
        <color rgba="0.52941 0.54902 0.54902 1"/>
      </material>
    </visual>
  </link>
  <joint name="l_leg_pitch_joint" type="continuous">
    <origin rpy="0 0 0" xyz="0 0.0 -0.1287"/>
    <parent link="l_leg_yaw"/>
    <child link="l_leg_pitch"/>
    <axis xyz="0 1 0"/>
    <limit effort="100" lower="-2.35" upper="0.78" velocity="47"/>
  </joint>
  <!--        ssss -->
  <transmission type="SimpleTransmission">
    <joint name="l_leg_pitch_joint"/>
    <actuator name="l_leg_pitch_motor"/>
  </transmission>
  <!-- sssssssss -->
  <link name="l_knee">
    <inertial>
      <origin rpy="0 0 0" xyz="0.00716677 -0.00006696 -0.11481925"/>
      <mass value="1.61274530"/>
      <inertia ixx="0.01103699" ixy="0.00000084" ixz="-0.00000711" iyy="0.01095123" iyz="0.00000987" izz="0.00087225"/>
    </inertial>
    <visual>
      <origin rpy="0 0 0" xyz="0 0 0"/>
      <geometry>
        <mesh filename="../../meshes/l_knee.STL"/>
      </geometry>
      <material name="">
        <color rgba="0.68627 0.65882 0.63922 1"/>
      </material>
    </visual>
  </link>
  <joint name="l_knee_pitch_joint" type="revolute">
    <origin rpy="0 0 0" xyz="0.0 0.0 -0.284"/>
    <parent link="l_leg_pitch"/>
    <child link="l_knee"/>
    <axis xyz="0 1 0"/>
    <limit effort="100" lower="0.0" upper="2.618" velocity="47"/>
  </joint>
  <!--        ssss -->
  <transmission type="SimpleTransmission">
    <joint name="l_knee_pitch_joint"/>
    <actuator name="l_knee_pitch_motor"/>
  </transmission>
  <!-- sssssssss -->
  <link name="l_foot_pitch">
    <inertial>
      <origin rpy="0 0 0" xyz="0.00000000 0.00000000 0"/>
      <mass value="0.07193524"/>
      <inertia ixx="0.00000692" ixy="0.00000000" ixz="0.00000000" iyy="0.00000692" iyz="0.00000000" izz="0.00001218"/>
    </inertial>
    <visual>
      <origin rpy="0 0 0" xyz="0 0 0"/>
      <geometry>
        <mesh filename="../../meshes/l_foot_pitch.STL"/>
      </geometry>
      <material name="">
        <color rgba="0.6902 0.65882 0.63922 1"/>
      </material>
    </visual>
  </link>
  <joint name="l_foot_pitch_joint" type="continuous">
    <origin rpy="0 0 0" xyz="0 0.0 -0.346"/>
    <parent link="l_knee"/>
    <child link="l_foot_pitch"/>
    <axis xyz="0 1 0"/>
    <limit effort="100" lower="-1.57" upper="1.57" velocity="25"/>
  </joint>
  <transmission type="SimpleTransmission">
    <joint name="l_foot_pitch_joint"/>
    <actuator name="l_foot_pitch_motor"/>
  </transmission>
  <!-- sssssssss -->
  <link name="l_foot_roll">
    <inertial>
      <origin rpy="0 0 0" xyz="0.03730703 -0.00000226 -0.03934407"/>
      <mass value="0.49004366"/>
      <inertia ixx="0.00037622" ixy="-0.00000003" ixz="-0.00004693" iyy="0.00157919" iyz="0.00000000" izz="0.00171680"/>
    </inertial>
    <visual>
      <origin rpy="0 0 0" xyz="0 0 0"/>
      <geometry>
        <mesh filename="../../meshes/l_foot_roll.STL"/>
      </geometry>
      <material name="">
        <color rgba="0.6902 0.65882 0.63922 1"/>
      </material>
    </visual>
    <visual>
      <origin rpy="0 0 0" xyz="-0.04937 0.04773 -0.0593"/>
      <geometry>
        <sphere radius="0.005"/>
      </geometry>
    </visual>
    <collision>
      <origin rpy="0 0 0" xyz="-0.04937 0.04773 -0.0593"/>
      <geometry>
        <sphere radius="0.005"/>
      </geometry>
    </collision>
    <visual>
      <origin rpy="0 0 0" xyz="-0.04937 -0.04773 -0.0593"/>
      <geometry>
        <sphere radius="0.005"/>
      </geometry>
    </visual>
    <collision>
      <origin rpy="0 0 0" xyz="-0.04937 -0.04773 -0.0593"/>
      <geometry>
        <sphere radius="0.005"/>
      </geometry>
    </collision>
    <visual>
      <origin rpy="0 0 0" xyz="0.13564 0.04773 -0.0593"/>
      <geometry>
        <sphere radius="0.005"/>
      </geometry>
    </visual>
    <collision>
      <origin rpy="0 0 0" xyz="0.13564 0.04773 -0.0593"/>
      <geometry>
        <sphere radius="0.005"/>
      </geometry>
    </collision>
    <visual>
      <origin rpy="0 0 0" xyz="0.13564 -0.04773 -0.0593"/>
      <geometry>
        <sphere radius="0.005"/>
      </geometry>
    </visual>
    <collision>
      <origin rpy="0 0 0" xyz="0.13564 -0.04773 -0.0593"/>
      <geometry>
        <sphere radius="0.005"/>
      </geometry>
    </collision>
  </link>
  <joint name="l_foot_roll_joint" type="continuous">
    <origin rpy="0 0 0" xyz="0 0 0"/>
    <parent link="l_foot_pitch"/>
    <child link="l_foot_roll"/>
    <axis xyz="1 0 0"/>
    <limit effort="100" lower="-1.39" upper="0.78" velocity="25"/>
  </joint>
  <transmission type="SimpleTransmission">
    <joint name="l_foot_roll_joint"/>
    <actuator name="l_foot_roll_motor"/>
  </transmission>
  <!-- sssssssss -->
  <frame link="l_foot_roll" name="l_foot_sole" xyz="0.04793 0.0 -0.0593"/>
  <frame link="l_foot_roll" name="l_foot_toe" xyz="0.16902 0.0 -0.0593"/>
  <frame link="l_foot_roll" name="l_foot_heel" xyz="-0.07316 0.0 -0.0593"/>
  <link name="r_leg_roll">
    <inertial>
      <origin rpy="0 0 0" xyz="0.00430146 0.00002709 -0.00851195"/>
      <mass value="1.71093008"/>
      <inertia ixx="0.00206092" ixy="0.00000197" ixz="-0.00006944" iyy="0.00277274" iyz="-0.00000510" izz="0.00370826"/>
    </inertial>
    <visual>
      <origin rpy="0 0 0" xyz="0 0 0"/>
      <geometry>
        <mesh filename="../../meshes/r_leg_roll.STL"/>
      </geometry>
      <material name="">
        <color rgba="0.6902 0.65882 0.63922 1"/>
      </material>
    </visual>
  </link>
  <joint name="r_leg_roll_joint" type="continuous">
    <origin rpy="0 0 0" xyz="-0.0024999 -0.087 -0.066"/>
    <parent link="torso"/>
    <child link="r_leg_roll"/>
    <axis xyz="1 0 0"/>
    <limit effort="100" lower="-1.57" upper="0.78" velocity="25"/>
  </joint>
  <!--        ssss -->
  <transmission type="SimpleTransmission">
    <joint name="r_leg_roll_joint"/>
    <actuator name="r_leg_roll_motor"/>
  </transmission>
  <!-- sssssssss -->
  <link name="r_leg_yaw">
    <inertial>
      <origin rpy="0 0 0" xyz="0.00000000 0.00322561 -0.09080869"/>
      <mass value="0.55762928"/>
      <inertia ixx="0.00213816" ixy="0.00000000" ixz="-0.00000003" iyy="0.00118284" iyz="-0.00004162" izz="0.00139547"/>
    </inertial>
    <visual>
      <origin rpy="0 0 0" xyz="0 0 0"/>
      <geometry>
        <mesh filename="../../meshes/r_leg_yaw.STL"/>
      </geometry>
      <material name="">
        <color rgba="0.650980392156863 0.619607843137255 0.588235294117647 1"/>
      </material>
    </visual>
  </link>
  <joint name="r_leg_yaw_joint" type="continuous">
    <origin rpy="0 0 0" xyz="0.0 0.0 0.0"/>
    <parent link="r_leg_roll"/>
    <child link="r_leg_yaw"/>
    <axis xyz="0 0 1"/>
    <limit effort="100" lower="-1.57" upper="1.57" velocity="25"/>
  </joint>
  <!--        ssss -->
  <transmission type="SimpleTransmission">
    <joint name="r_leg_yaw_joint"/>
    <actuator name="r_leg_yaw_motor"/>
  </transmission>
  <!-- sssssssss -->
  <link name="r_leg_pitch">
    <inertial>
      <origin rpy="0 0 0" xyz="0.00185677 -0.01023458 -0.08558380"/>
      <mass value="4.43577451"/>
      <inertia ixx="0.04271209" ixy="-0.00000777" ixz="-0.00143032" iyy="0.04420935" iyz="-0.00092942" izz="0.01102339"/>
    </inertial>
    <visual>
      <origin rpy="0 0 0" xyz="0 0 0"/>
      <geometry>
        <mesh filename="../../meshes/r_leg_pitch.STL"/>
      </geometry>
      <material name="">
        <color rgba="0.529411764705882 0.549019607843137 0.549019607843137 1"/>
      </material>
    </visual>
  </link>
  <joint name="r_leg_pitch_joint" type="continuous">
    <origin rpy="0 0 0" xyz="0 0 -0.1287"/>
    <parent link="r_leg_yaw"/>
    <child link="r_leg_pitch"/>
    <axis xyz="0 1 0"/>
    <limit effort="100" lower="-2.35" upper="0.78" velocity="47"/>
  </joint>
  <!--        ssss -->
  <transmission type="SimpleTransmission">
    <joint name="r_leg_pitch_joint"/>
    <actuator name="r_leg_pitch_motor"/>
  </transmission>
  <!-- sssssssss -->
  <link name="r_knee">
    <inertial>
      <origin rpy="0 0 0" xyz="0.00716677 0.00006696 -0.11481925"/>
      <mass value="1.61274530"/>
      <inertia ixx="0.01103699" ixy="0.00000084" ixz="-0.00000711" iyy="0.01095123" iyz="0.00000987" izz="0.00087225"/>
    </inertial>
    <visual>
      <origin rpy="0 0 0" xyz="0 0 0"/>
      <geometry>
        <mesh filename="../../meshes/r_knee.STL"/>
      </geometry>
      <material name="">
        <color rgba="0.686274509803922 0.658823529411765 0.63921568627451 1"/>
      </material>
    </visual>
  </link>
  <joint name="r_knee_pitch_joint" type="revolute">
    <origin rpy="0 0 0" xyz="0 0 -0.284"/>
    <parent link="r_leg_pitch"/>
    <child link="r_knee"/>
    <axis xyz="0 1 0"/>
    <limit effort="100" lower="0.0" upper="2.618" velocity="47"/>
  </joint>
  <!--        ssss -->
  <transmission type="SimpleTransmission">
    <joint name="r_knee_pitch_joint"/>
    <actuator name="r_knee_pitch_motor"/>
  </transmission>
  <!-- sssssssss -->
  <link name="r_foot_pitch">
    <inertial>
      <origin rpy="0 0 0" xyz="0 0.00000000 0"/>
      <mass value="0.07193524"/>
      <inertia ixx="0.00000692" ixy="0" ixz="0" iyy="0.00000692" iyz="0" izz="0.00001218"/>
    </inertial>
    <visual>
      <origin rpy="0 0 0" xyz="0 0 0"/>
      <geometry>
        <mesh filename="../../meshes/r_foot_pitch.STL"/>
      </geometry>
      <material name="">
        <color rgba="0.690196078431373 0.658823529411765 0.63921568627451 1"/>
      </material>
    </visual>
  </link>
  <joint name="r_foot_pitch_joint" type="continuous">
    <origin rpy="0 0 0" xyz="0 0 -0.346"/>
    <parent link="r_knee"/>
    <child link="r_foot_pitch"/>
    <axis xyz="0 1 0"/>
    <limit effort="100" lower="-1.57" upper="1.57" velocity="25"/>
  </joint>
  <!--        ssss -->
  <transmission type="SimpleTransmission">
    <joint name="r_foot_pitch_joint"/>
    <actuator name="r_foot_pitch_motor"/>
  </transmission>
  <!-- sssssssss -->
  <link name="r_foot_roll">
    <inertial>
      <origin rpy="0 0 0" xyz="0.03730703 0.00000225 -0.03934407"/>
      <mass value="0.49004366"/>
      <inertia ixx="0.00037622" ixy="0.00000003" ixz="-0.00004693" iyy="0.00157919" iyz="0.00000000" izz="0.00171680"/>
    </inertial>
    <visual>
      <origin rpy="0 0 0" xyz="0 0 0"/>
      <geometry>
        <mesh filename="../../meshes/r_foot_roll.STL"/>
      </geometry>
      <material name="">
        <color rgba="0.690196078431373 0.658823529411765 0.63921568627451 1"/>
      </material>
    </visual>
    <visual>
      <origin rpy="0 0 0" xyz="-0.04937 0.04773 -0.0465"/>
      <geometry>
        <sphere radius="0.005"/>
      </geometry>
    </visual>
    <collision>
      <origin rpy="0 0 0" xyz="-0.04937 0.04773 -0.0593"/>
      <geometry>
        <sphere radius="0.005"/>
      </geometry>
    </collision>
    <visual>
      <origin rpy="0 0 0" xyz="-0.04937 -0.04773 -0.0593"/>
      <geometry>
        <sphere radius="0.005"/>
      </geometry>
    </visual>
    <collision>
      <origin rpy="0 0 0" xyz="-0.04937 -0.04773 -0.0593"/>
      <geometry>
        <sphere radius="0.005"/>
      </geometry>
    </collision>
    <visual>
      <origin rpy="0 0 0" xyz="0.13564 0.04773 -0.0593"/>
      <geometry>
        <sphere radius="0.005"/>
      </geometry>
    </visual>
    <collision>
      <origin rpy="0 0 0" xyz="0.13564 0.04773 -0.0593"/>
      <geometry>
        <sphere radius="0.005"/>
      </geometry>
    </collision>
    <visual>
      <origin rpy="0 0 0" xyz="0.13564 -0.04773 -0.0593"/>
      <geometry>
        <sphere radius="0.005"/>
      </geometry>
    </visual>
    <collision>
      <origin rpy="0 0 0" xyz="0.13564 -0.04773 -0.0593"/>
      <geometry>
        <sphere radius="0.005"/>
      </geometry>
    </collision>
  </link>
  <joint name="r_foot_roll_joint" type="continuous">
    <origin rpy="0 0 0" xyz="0 0 0"/>
    <parent link="r_foot_pitch"/>
    <child link="r_foot_roll"/>
    <axis xyz="1 0 0"/>
    <limit effort="100" lower="-1.39" upper="0.78" velocity="25"/>
  </joint>
  <!--        ssss -->
  <transmission type="SimpleTransmission">
    <joint name="r_foot_roll_joint"/>
    <actuator name="r_foot_roll_motor"/>
  </transmission>
  <!-- sssssssss -->
  <frame link="r_foot_roll" name="r_foot_sole" xyz="0.04793 0.0 -0.0593"/>
  <frame link="r_foot_roll" name="r_foot_toe" xyz="0.16902 0.0 -0.0593"/>
  <frame link="r_foot_roll" name="r_foot_heel" xyz="-0.07316 -0.0 -0.0593"/>
</robot>

