<?xml version="1.0" ?>
<!-- =================================================================================== -->
<!-- |    This document was autogenerated by xacro from /home/fandes/workspace/kuavo-ros-control/src/humanoid-control/humanoid_interface_drake/models/biped_gen4.2/urdf/biped_v3_full.xacro | -->
<!-- |    EDITING THIS FILE BY HAND IS NOT RECOMMENDED                                 | -->
<!-- =================================================================================== -->
<robot name="biped_v3_full" xmlns:drake="https://drake.mit.edu">
  <link name="torso">
    <inertial>
      <origin rpy="0 0 0" xyz="-0.01779947 0.00029663 0.18176446"/>
      <mass value="25.87904316"/>
      <inertia ixx="0.84217451" ixy="-0.00019450" ixz="0.06746774" iyy="0.73769958" iyz="-0.00007935" izz="0.24371683"/>
    </inertial>
    <visual>
      <origin rpy="0 0 0" xyz="0 0 0"/>
      <geometry>
        <mesh filename="../../meshes/torso.STL"/>
      </geometry>
      <material name="">
        <color rgba="0.43137 0.45098 0.43137 1"/>
      </material>
    </visual>
    <!-- <collision>
      <origin xyz="0 0 0" rpy="0 0 0" />
      <geometry>
        <mesh filename="../../meshes/torso.STL" />
      </geometry>
    </collision> -->
  </link>
  <link name="l_leg_roll">
    <inertial>
      <origin rpy="0 0 0" xyz="-0.00430148 -0.00002708 -0.00851195"/>
      <mass value="1.71093115"/>
      <inertia ixx="0.00206092" ixy="-0.00000197" ixz="-0.00006944" iyy="0.00277274" iyz="0.00000510" izz="0.00370826"/>
    </inertial>
    <visual>
      <origin rpy="0 0 0" xyz="0 0 0"/>
      <geometry>
        <mesh filename="../../meshes/l_leg_roll.STL"/>
      </geometry>
      <material name="">
        <color rgba="0.6902 0.65882 0.63922 1"/>
      </material>
    </visual>
  </link>
  <joint name="l_leg_roll_joint" type="continuous">
    <origin rpy="0 0 0" xyz="-0.0024999 0.087 -0.066"/>
    <parent link="torso"/>
    <child link="l_leg_roll"/>
    <axis xyz="1 0 0"/>
    <limit effort="100" lower="-0.78" upper="1.57" velocity="25"/>
  </joint>
  <!--        ssss -->
  <transmission type="SimpleTransmission">
    <joint name="l_leg_roll_joint"/>
    <actuator name="l_leg_roll_motor"/>
  </transmission>
  <!-- sssssssss -->
  <link name="l_leg_yaw">
    <inertial>
      <origin rpy="0 0 0" xyz="0.00000000 -0.00322560 -0.09080869"/>
      <mass value="0.55762936"/>
      <inertia ixx="0.00213816" ixy="0.00000000" ixz="-0.00000003" iyy="0.00118284" iyz="0.00004162" izz="0.00139547"/>
    </inertial>
    <visual>
      <origin rpy="0 0 0" xyz="0 0 0"/>
      <geometry>
        <mesh filename="../../meshes/l_leg_yaw.STL"/>
      </geometry>
      <material name="">
        <color rgba="0.65098 0.61961 0.58824 1"/>
      </material>
    </visual>
  </link>
  <joint name="l_leg_yaw_joint" type="continuous">
    <origin rpy="0 0 0" xyz="0 0 0"/>
    <parent link="l_leg_roll"/>
    <child link="l_leg_yaw"/>
    <axis xyz="0 0 1"/>
    <limit effort="100" lower="-1.57" upper="1.57" velocity="25"/>
  </joint>
  <!--        ssss -->
  <transmission type="SimpleTransmission">
    <joint name="l_leg_yaw_joint"/>
    <actuator name="l_leg_yaw_motor"/>
  </transmission>
  <!-- sssssssss -->
  <link name="l_leg_pitch">
    <inertial>
      <origin rpy="0 0 0" xyz="0.00185677 0.01023458 -0.08558380"/>
      <mass value="4.43577451"/>
      <inertia ixx="0.04271209" ixy="-0.00000777" ixz="-0.00143032" iyy="0.04341831" iyz="-0.00092942" izz="0.01102339"/>
    </inertial>
    <visual>
      <origin rpy="0 0 0" xyz="0 0 0"/>
      <geometry>
        <mesh filename="../../meshes/l_leg_pitch.STL"/>
      </geometry>
      <material name="">
        <color rgba="0.52941 0.54902 0.54902 1"/>
      </material>
    </visual>
  </link>
  <joint name="l_leg_pitch_joint" type="continuous">
    <origin rpy="0 0 0" xyz="0 0.0 -0.1287"/>
    <parent link="l_leg_yaw"/>
    <child link="l_leg_pitch"/>
    <axis xyz="0 1 0"/>
    <limit effort="100" lower="-2.35" upper="0.78" velocity="47"/>
  </joint>
  <!--        ssss -->
  <transmission type="SimpleTransmission">
    <joint name="l_leg_pitch_joint"/>
    <actuator name="l_leg_pitch_motor"/>
  </transmission>
  <!-- sssssssss -->
  <link name="l_knee">
    <inertial>
      <origin rpy="0 0 0" xyz="0.00716677 -0.00006696 -0.11481925"/>
      <mass value="1.61274530"/>
      <inertia ixx="0.01103699" ixy="0.00000084" ixz="-0.00000711" iyy="0.01095123" iyz="0.00000987" izz="0.00087225"/>
    </inertial>
    <visual>
      <origin rpy="0 0 0" xyz="0 0 0"/>
      <geometry>
        <mesh filename="../../meshes/l_knee.STL"/>
      </geometry>
      <material name="">
        <color rgba="0.68627 0.65882 0.63922 1"/>
      </material>
    </visual>
  </link>
  <joint name="l_knee_pitch_joint" type="revolute">
    <origin rpy="0 0 0" xyz="0.0 0.0 -0.284"/>
    <parent link="l_leg_pitch"/>
    <child link="l_knee"/>
    <axis xyz="0 1 0"/>
    <limit effort="100" lower="0.0" upper="2.618" velocity="47"/>
  </joint>
  <!--        ssss -->
  <transmission type="SimpleTransmission">
    <joint name="l_knee_pitch_joint"/>
    <actuator name="l_knee_pitch_motor"/>
  </transmission>
  <!-- sssssssss -->
  <link name="l_foot_pitch">
    <inertial>
      <origin rpy="0 0 0" xyz="0.00000000 0.00000000 0"/>
      <mass value="0.07193524"/>
      <inertia ixx="0.00000692" ixy="0.00000000" ixz="0.00000000" iyy="0.00000692" iyz="0.00000000" izz="0.00001218"/>
    </inertial>
    <visual>
      <origin rpy="0 0 0" xyz="0 0 0"/>
      <geometry>
        <mesh filename="../../meshes/l_foot_pitch.STL"/>
      </geometry>
      <material name="">
        <color rgba="0.6902 0.65882 0.63922 1"/>
      </material>
    </visual>
  </link>
  <joint name="l_foot_pitch_joint" type="continuous">
    <origin rpy="0 0 0" xyz="0 0.0 -0.346"/>
    <parent link="l_knee"/>
    <child link="l_foot_pitch"/>
    <axis xyz="0 1 0"/>
    <limit effort="100" lower="-1.57" upper="1.57" velocity="25"/>
  </joint>
  <transmission type="SimpleTransmission">
    <joint name="l_foot_pitch_joint"/>
    <actuator name="l_foot_pitch_motor"/>
  </transmission>
  <!-- sssssssss -->
  <link name="l_foot_roll">
    <inertial>
      <origin rpy="0 0 0" xyz="0.03730703 -0.00000226 -0.03934407"/>
      <mass value="0.49004366"/>
      <inertia ixx="0.00037622" ixy="-0.00000003" ixz="-0.00004693" iyy="0.00157919" iyz="0.00000000" izz="0.00171680"/>
    </inertial>
    <visual>
      <origin rpy="0 0 0" xyz="0 0 0"/>
      <geometry>
        <mesh filename="../../meshes/l_foot_roll.STL"/>
      </geometry>
      <material name="">
        <color rgba="0.6902 0.65882 0.63922 1"/>
      </material>
    </visual>
    <visual>
      <origin rpy="0 0 0" xyz="-0.04937 0.04773 -0.0593"/>
      <geometry>
        <sphere radius="0.005"/>
      </geometry>
    </visual>
    <collision>
      <origin rpy="0 0 0" xyz="-0.04937 0.04773 -0.0593"/>
      <geometry>
        <sphere radius="0.005"/>
      </geometry>
    </collision>
    <visual>
      <origin rpy="0 0 0" xyz="-0.04937 -0.04773 -0.0593"/>
      <geometry>
        <sphere radius="0.005"/>
      </geometry>
    </visual>
    <collision>
      <origin rpy="0 0 0" xyz="-0.04937 -0.04773 -0.0593"/>
      <geometry>
        <sphere radius="0.005"/>
      </geometry>
    </collision>
    <visual>
      <origin rpy="0 0 0" xyz="0.13564 0.04773 -0.0593"/>
      <geometry>
        <sphere radius="0.005"/>
      </geometry>
    </visual>
    <collision>
      <origin rpy="0 0 0" xyz="0.13564 0.04773 -0.0593"/>
      <geometry>
        <sphere radius="0.005"/>
      </geometry>
    </collision>
    <visual>
      <origin rpy="0 0 0" xyz="0.13564 -0.04773 -0.0593"/>
      <geometry>
        <sphere radius="0.005"/>
      </geometry>
    </visual>
    <collision>
      <origin rpy="0 0 0" xyz="0.13564 -0.04773 -0.0593"/>
      <geometry>
        <sphere radius="0.005"/>
      </geometry>
    </collision>
  </link>
  <joint name="l_foot_roll_joint" type="continuous">
    <origin rpy="0 0 0" xyz="0 0 0"/>
    <parent link="l_foot_pitch"/>
    <child link="l_foot_roll"/>
    <axis xyz="1 0 0"/>
    <limit effort="100" lower="-1.39" upper="0.78" velocity="25"/>
  </joint>
  <transmission type="SimpleTransmission">
    <joint name="l_foot_roll_joint"/>
    <actuator name="l_foot_roll_motor"/>
  </transmission>
  <!-- sssssssss -->
  <frame link="l_foot_roll" name="l_foot_sole" xyz="0.04793 0.0 -0.0593"/>
  <frame link="l_foot_roll" name="l_foot_toe" xyz="0.16902 0.0 -0.0593"/>
  <frame link="l_foot_roll" name="l_foot_heel" xyz="-0.07316 0.0 -0.0593"/>
  <link name="r_leg_roll">
    <inertial>
      <origin rpy="0 0 0" xyz="0.00430146 0.00002709 -0.00851195"/>
      <mass value="1.71093008"/>
      <inertia ixx="0.00206092" ixy="0.00000197" ixz="-0.00006944" iyy="0.00277274" iyz="-0.00000510" izz="0.00370826"/>
    </inertial>
    <visual>
      <origin rpy="0 0 0" xyz="0 0 0"/>
      <geometry>
        <mesh filename="../../meshes/r_leg_roll.STL"/>
      </geometry>
      <material name="">
        <color rgba="0.6902 0.65882 0.63922 1"/>
      </material>
    </visual>
  </link>
  <joint name="r_leg_roll_joint" type="continuous">
    <origin rpy="0 0 0" xyz="-0.0024999 -0.087 -0.066"/>
    <parent link="torso"/>
    <child link="r_leg_roll"/>
    <axis xyz="1 0 0"/>
    <limit effort="100" lower="-1.57" upper="0.78" velocity="25"/>
  </joint>
  <!--        ssss -->
  <transmission type="SimpleTransmission">
    <joint name="r_leg_roll_joint"/>
    <actuator name="r_leg_roll_motor"/>
  </transmission>
  <!-- sssssssss -->
  <link name="r_leg_yaw">
    <inertial>
      <origin rpy="0 0 0" xyz="0.00000000 0.00322561 -0.09080869"/>
      <mass value="0.55762928"/>
      <inertia ixx="0.00213816" ixy="0.00000000" ixz="-0.00000003" iyy="0.00118284" iyz="-0.00004162" izz="0.00139547"/>
    </inertial>
    <visual>
      <origin rpy="0 0 0" xyz="0 0 0"/>
      <geometry>
        <mesh filename="../../meshes/r_leg_yaw.STL"/>
      </geometry>
      <material name="">
        <color rgba="0.650980392156863 0.619607843137255 0.588235294117647 1"/>
      </material>
    </visual>
  </link>
  <joint name="r_leg_yaw_joint" type="continuous">
    <origin rpy="0 0 0" xyz="0.0 0.0 0.0"/>
    <parent link="r_leg_roll"/>
    <child link="r_leg_yaw"/>
    <axis xyz="0 0 1"/>
    <limit effort="100" lower="-1.57" upper="1.57" velocity="25"/>
  </joint>
  <!--        ssss -->
  <transmission type="SimpleTransmission">
    <joint name="r_leg_yaw_joint"/>
    <actuator name="r_leg_yaw_motor"/>
  </transmission>
  <!-- sssssssss -->
  <link name="r_leg_pitch">
    <inertial>
      <origin rpy="0 0 0" xyz="0.00185677 -0.01023458 -0.08558380"/>
      <mass value="4.43577451"/>
      <inertia ixx="0.04271209" ixy="-0.00000777" ixz="-0.00143032" iyy="0.04420935" iyz="-0.00092942" izz="0.01102339"/>
    </inertial>
    <visual>
      <origin rpy="0 0 0" xyz="0 0 0"/>
      <geometry>
        <mesh filename="../../meshes/r_leg_pitch.STL"/>
      </geometry>
      <material name="">
        <color rgba="0.529411764705882 0.549019607843137 0.549019607843137 1"/>
      </material>
    </visual>
  </link>
  <joint name="r_leg_pitch_joint" type="continuous">
    <origin rpy="0 0 0" xyz="0 0 -0.1287"/>
    <parent link="r_leg_yaw"/>
    <child link="r_leg_pitch"/>
    <axis xyz="0 1 0"/>
    <limit effort="100" lower="-2.35" upper="0.78" velocity="47"/>
  </joint>
  <!--        ssss -->
  <transmission type="SimpleTransmission">
    <joint name="r_leg_pitch_joint"/>
    <actuator name="r_leg_pitch_motor"/>
  </transmission>
  <!-- sssssssss -->
  <link name="r_knee">
    <inertial>
      <origin rpy="0 0 0" xyz="0.00716677 0.00006696 -0.11481925"/>
      <mass value="1.61274530"/>
      <inertia ixx="0.01103699" ixy="0.00000084" ixz="-0.00000711" iyy="0.01095123" iyz="0.00000987" izz="0.00087225"/>
    </inertial>
    <visual>
      <origin rpy="0 0 0" xyz="0 0 0"/>
      <geometry>
        <mesh filename="../../meshes/r_knee.STL"/>
      </geometry>
      <material name="">
        <color rgba="0.686274509803922 0.658823529411765 0.63921568627451 1"/>
      </material>
    </visual>
  </link>
  <joint name="r_knee_pitch_joint" type="revolute">
    <origin rpy="0 0 0" xyz="0 0 -0.284"/>
    <parent link="r_leg_pitch"/>
    <child link="r_knee"/>
    <axis xyz="0 1 0"/>
    <limit effort="100" lower="0.0" upper="2.618" velocity="47"/>
  </joint>
  <!--        ssss -->
  <transmission type="SimpleTransmission">
    <joint name="r_knee_pitch_joint"/>
    <actuator name="r_knee_pitch_motor"/>
  </transmission>
  <!-- sssssssss -->
  <link name="r_foot_pitch">
    <inertial>
      <origin rpy="0 0 0" xyz="0 0.00000000 0"/>
      <mass value="0.07193524"/>
      <inertia ixx="0.00000692" ixy="0" ixz="0" iyy="0.00000692" iyz="0" izz="0.00001218"/>
    </inertial>
    <visual>
      <origin rpy="0 0 0" xyz="0 0 0"/>
      <geometry>
        <mesh filename="../../meshes/r_foot_pitch.STL"/>
      </geometry>
      <material name="">
        <color rgba="0.690196078431373 0.658823529411765 0.63921568627451 1"/>
      </material>
    </visual>
  </link>
  <joint name="r_foot_pitch_joint" type="continuous">
    <origin rpy="0 0 0" xyz="0 0 -0.346"/>
    <parent link="r_knee"/>
    <child link="r_foot_pitch"/>
    <axis xyz="0 1 0"/>
    <limit effort="100" lower="-1.57" upper="1.57" velocity="25"/>
  </joint>
  <!--        ssss -->
  <transmission type="SimpleTransmission">
    <joint name="r_foot_pitch_joint"/>
    <actuator name="r_foot_pitch_motor"/>
  </transmission>
  <!-- sssssssss -->
  <link name="r_foot_roll">
    <inertial>
      <origin rpy="0 0 0" xyz="0.03730703 0.00000225 -0.03934407"/>
      <mass value="0.49004366"/>
      <inertia ixx="0.00037622" ixy="0.00000003" ixz="-0.00004693" iyy="0.00157919" iyz="0.00000000" izz="0.00171680"/>
    </inertial>
    <visual>
      <origin rpy="0 0 0" xyz="0 0 0"/>
      <geometry>
        <mesh filename="../../meshes/r_foot_roll.STL"/>
      </geometry>
      <material name="">
        <color rgba="0.690196078431373 0.658823529411765 0.63921568627451 1"/>
      </material>
    </visual>
    <visual>
      <origin rpy="0 0 0" xyz="-0.04937 0.04773 -0.0465"/>
      <geometry>
        <sphere radius="0.005"/>
      </geometry>
    </visual>
    <collision>
      <origin rpy="0 0 0" xyz="-0.04937 0.04773 -0.0593"/>
      <geometry>
        <sphere radius="0.005"/>
      </geometry>
    </collision>
    <visual>
      <origin rpy="0 0 0" xyz="-0.04937 -0.04773 -0.0593"/>
      <geometry>
        <sphere radius="0.005"/>
      </geometry>
    </visual>
    <collision>
      <origin rpy="0 0 0" xyz="-0.04937 -0.04773 -0.0593"/>
      <geometry>
        <sphere radius="0.005"/>
      </geometry>
    </collision>
    <visual>
      <origin rpy="0 0 0" xyz="0.13564 0.04773 -0.0593"/>
      <geometry>
        <sphere radius="0.005"/>
      </geometry>
    </visual>
    <collision>
      <origin rpy="0 0 0" xyz="0.13564 0.04773 -0.0593"/>
      <geometry>
        <sphere radius="0.005"/>
      </geometry>
    </collision>
    <visual>
      <origin rpy="0 0 0" xyz="0.13564 -0.04773 -0.0593"/>
      <geometry>
        <sphere radius="0.005"/>
      </geometry>
    </visual>
    <collision>
      <origin rpy="0 0 0" xyz="0.13564 -0.04773 -0.0593"/>
      <geometry>
        <sphere radius="0.005"/>
      </geometry>
    </collision>
  </link>
  <joint name="r_foot_roll_joint" type="continuous">
    <origin rpy="0 0 0" xyz="0 0 0"/>
    <parent link="r_foot_pitch"/>
    <child link="r_foot_roll"/>
    <axis xyz="1 0 0"/>
    <limit effort="100" lower="-1.39" upper="0.78" velocity="25"/>
  </joint>
  <!--        ssss -->
  <transmission type="SimpleTransmission">
    <joint name="r_foot_roll_joint"/>
    <actuator name="r_foot_roll_motor"/>
  </transmission>
  <!-- sssssssss -->
  <frame link="r_foot_roll" name="r_foot_sole" xyz="0.04793 0.0 -0.0593"/>
  <frame link="r_foot_roll" name="r_foot_toe" xyz="0.16902 0.0 -0.0593"/>
  <frame link="r_foot_roll" name="r_foot_heel" xyz="-0.07316 -0.0 -0.0593"/>
  <!-- =========================================================== Arms ================================================================= -->
  <link name="l_arm_pitch">
    <inertial>
      <origin rpy="0 0 0" xyz="0.0146835191418715 -0.0166604103758634 -6.82857133371129E-05"/>
      <mass value="0.794"/>
      <inertia ixx="0.0002674432873971" ixy="-2.5654089149164E-05" ixz="-1.72966133127553E-07" iyy="0.000125796784291983" iyz="-1.66717296343013E-06" izz="0.000196186976742156"/>
    </inertial>
    <visual>
      <origin rpy="0 0 0" xyz="0 0 0"/>
      <geometry>
        <mesh filename="../../meshes/l_arm_pitch.STL"/>
      </geometry>
      <material name="">
        <color rgba="1 1 1 1"/>
      </material>
    </visual>
  </link>
  <joint name="l_arm_pitch" type="continuous">
    <origin rpy="0 0 0" xyz="-0.0175475823124921 0.262700000000031 0.324500000000024"/>
    <parent link="torso"/>
    <child link="l_arm_pitch"/>
    <axis xyz="0 1 0"/>
    <limit effort="100" lower="-1.57" upper="1.57" velocity="35"/>
  </joint>
  <transmission type="SimpleTransmission">
    <joint name="l_arm_pitch"/>
    <actuator name="l_arm_pitch_motor"/>
  </transmission>
  <link name="l_arm_roll">
    <inertial>
      <origin rpy="0 0 0" xyz="0.0222872651779299 0.0156945544195473 -0.0202262244341484"/>
      <mass value="0.20735"/>
      <inertia ixx="0.000160370067223081" ixy="6.30811840859269E-06" ixz="-1.13259246453495E-05" iyy="0.000262365778589962" iyz="3.14941259087024E-05" izz="0.00023601403628197"/>
    </inertial>
    <visual>
      <origin rpy="0 0 0" xyz="0 0 0"/>
      <geometry>
        <mesh filename="../../meshes/l_arm_roll.STL"/>
      </geometry>
      <material name="">
        <color rgba="1 1 1 1"/>
      </material>
    </visual>
  </link>
  <joint name="l_arm_roll" type="continuous">
    <origin rpy="0 0 0" xyz="0 0 0"/>
    <parent link="l_arm_pitch"/>
    <child link="l_arm_roll"/>
    <axis xyz="1 0 0"/>
    <limit effort="100" lower="-1.57" upper="1.57" velocity="35"/>
  </joint>
  <transmission type="SimpleTransmission">
    <joint name="l_arm_roll"/>
    <actuator name="l_arm_roll_motor"/>
  </transmission>
  <link name="l_arm_yaw">
    <inertial>
      <origin rpy="0 0 0" xyz="6.16940440451783E-05 0.00525815062784063 -0.128821944854616"/>
      <mass value="1.120632"/>
      <inertia ixx="7.00575957554699E-05" ixy="-6.81658291272877E-10" ixz="2.69427050743199E-10" iyy="8.53612265336777E-05" iyz="6.95899873075699E-06" izz="8.82223899453285E-05"/>
    </inertial>
    <visual>
      <origin rpy="0 0 0" xyz="0 0 0"/>
      <geometry>
        <mesh filename="../../meshes/l_arm_yaw.STL"/>
      </geometry>
      <material name="">
        <color rgba="1 1 1 1"/>
      </material>
    </visual>
  </link>
  <joint name="l_arm_yaw" type="continuous">
    <origin rpy="0 0 0" xyz="0 0 0"/>
    <parent link="l_arm_roll"/>
    <child link="l_arm_yaw"/>
    <axis xyz="0 0 1"/>
    <limit effort="100" lower="-1.57" upper="1.57" velocity="35"/>
  </joint>
  <transmission type="SimpleTransmission">
    <joint name="l_arm_yaw"/>
    <actuator name="l_arm_yaw_motor"/>
  </transmission>
  <link name="l_forearm_pitch">
    <inertial>
      <origin rpy="0 0 0" xyz="-1.4281929799409E-05 0.00938313949959718 -0.0522687552263489"/>
      <mass value="0.395825"/>
      <inertia ixx="9.558084476069E-05" ixy="-4.53863490387433E-08" ixz="5.39342118513253E-08" iyy="0.000126326373178391" iyz="-9.58160032696958E-06" izz="0.000121032474884238"/>
    </inertial>
    <visual>
      <origin rpy="0 0 0" xyz="0 0 0"/>
      <geometry>
        <mesh filename="../../meshes/l_forearm_pitch.STL"/>
      </geometry>
      <material name="">
        <color rgba="1 1 1 1"/>
      </material>
    </visual>
  </link>
  <joint name="l_forearm_pitch" type="continuous">
    <origin rpy="0 0 0" xyz="0 0 -0.163599999999998"/>
    <parent link="l_arm_yaw"/>
    <child link="l_forearm_pitch"/>
    <axis xyz="0 1 0"/>
    <limit effort="100" lower="-1.57" upper="1.57" velocity="35"/>
  </joint>
  <transmission type="SimpleTransmission">
    <joint name="l_forearm_pitch"/>
    <actuator name="l_forearm_pitch_motor"/>
  </transmission>
  <link name="l_hand_yaw">
    <inertial>
      <origin rpy="0 0 0" xyz="0.000113133463122583 0.00969227839919062 0.0817960696431681"/>
      <mass value="0.380792"/>
      <inertia ixx="7.64923984145487E-05" ixy="8.51098127601464E-09" ixz="-1.4070355859132E-08" iyy="0.000122231132554914" iyz="1.11226968994633E-06" izz="8.44935061342021E-05"/>
    </inertial>
    <visual>
      <origin rpy="0 0 0" xyz="0 0 0"/>
      <geometry>
        <mesh filename="../../meshes/l_hand_yaw.STL"/>
      </geometry>
      <material name="">
        <color rgba="1 1 1 1"/>
      </material>
    </visual>
  </link>
  <joint name="l_hand_yaw" type="continuous">
    <origin rpy="0 0 0" xyz="0 0 -0.191049997298861"/>
    <parent link="l_forearm_pitch"/>
    <child link="l_hand_yaw"/>
    <axis xyz="0 0 1"/>
    <limit effort="100" lower="-1.57" upper="1.57" velocity="35"/>
  </joint>
  <transmission type="SimpleTransmission">
    <joint name="l_hand_yaw"/>
    <actuator name="l_hand_yaw_motor"/>
  </transmission>
  <link name="l_hand_pitch">
    <inertial>
      <origin rpy="0 0 0" xyz="0.00810609786663821 0.00489663150092601 0.00622488608908427"/>
      <mass value="0.376651"/>
      <inertia ixx="4.77321490368476E-05" ixy="3.05261917457107E-06" ixz="4.77827164947654E-06" iyy="3.43814769749139E-05" iyz="-4.59311499587155E-06" izz="2.49955336560135E-05"/>
    </inertial>
    <visual>
      <origin rpy="0 0 0" xyz="0 0 0"/>
      <geometry>
        <mesh filename="../../meshes/l_hand_pitch.STL"/>
      </geometry>
      <material name="">
        <color rgba="1 1 1 1"/>
      </material>
    </visual>
  </link>
  <joint name="l_hand_pitch" type="continuous">
    <origin rpy="0 0 0" xyz="0 0 0"/>
    <parent link="l_hand_yaw"/>
    <child link="l_hand_pitch"/>
    <axis xyz="0 1 0"/>
    <limit effort="100" lower="-1.57" upper="1.57" velocity="35"/>
  </joint>
  <transmission type="SimpleTransmission">
    <joint name="l_hand_pitch"/>
    <actuator name="l_hand_pitch_motor"/>
  </transmission>
  <link name="l_hand_roll">
    <inertial>
      <origin rpy="0 0 0" xyz="0.0055750097939089 0.00647363667890594 -0.0826245715087526"/>
      <mass value="0.704669"/>
      <inertia ixx="8.04371746531483E-05" ixy="2.770174858381E-07" ixz="-4.63354764745673E-06" iyy="0.000116536814280971" iyz="1.04534418501281E-05" izz="0.000111690600253046"/>
    </inertial>
    <visual>
      <origin rpy="0 0 0" xyz="0 0 0"/>
      <geometry>
        <mesh filename="../../meshes/l_hand_roll.STL"/>
      </geometry>
      <material name="">
        <color rgba="1 1 1 1"/>
      </material>
    </visual>
  </link>
  <joint name="l_hand_roll" type="continuous">
    <origin rpy="0 0 0" xyz="0 0 0"/>
    <parent link="l_hand_pitch"/>
    <child link="l_hand_roll"/>
    <axis xyz="1 0 0"/>
    <limit effort="100" lower="-1.57" upper="1.57" velocity="35"/>
  </joint>
  <transmission type="SimpleTransmission">
    <joint name="l_hand_roll"/>
    <actuator name="l_hand_roll_motor"/>
  </transmission>
  <!-- right arm -->
  <link name="r_arm_pitch">
    <inertial>
      <origin rpy="0 0 0" xyz="0.0146743511434554 0.0168298008224051 -8.16711977456031E-05"/>
      <mass value="0.794"/>
      <inertia ixx="0.000267364314112701" ixy="2.58822573731612E-05" ixz="-1.74450019197634E-07" iyy="0.000125724274127356" iyz="1.71810516637517E-06" izz="0.000196179895851995"/>
    </inertial>
    <visual>
      <origin rpy="0 0 0" xyz="0 0 0"/>
      <geometry>
        <mesh filename="../../meshes/r_arm_pitch.STL"/>
      </geometry>
      <material name="">
        <color rgba="1 1 1 1"/>
      </material>
    </visual>
  </link>
  <joint name="r_arm_pitch" type="continuous">
    <origin rpy="0 0 0" xyz="-0.0175475823119764 -0.262700000000031 0.324500000000024"/>
    <parent link="torso"/>
    <child link="r_arm_pitch"/>
    <axis xyz="0 1 0"/>
    <limit effort="100" lower="-1.57" upper="1.57" velocity="35"/>
  </joint>
  <transmission type="SimpleTransmission">
    <joint name="r_arm_pitch"/>
    <actuator name="r_arm_pitch_motor"/>
  </transmission>
  <link name="r_arm_roll">
    <inertial>
      <origin rpy="0 0 0" xyz="0.0223009070030529 -0.0156950170482436 -0.0202307747650334"/>
      <mass value="0.20735"/>
      <inertia ixx="0.00016058853411588" ixy="-6.25733649402466E-06" ixz="-1.13236198708706E-05" iyy="0.000262566981542989" iyz="-3.14930415013909E-05" izz="0.000236151535262186"/>
    </inertial>
    <visual>
      <origin rpy="0 0 0" xyz="0 0 0"/>
      <geometry>
        <mesh filename="../../meshes/r_arm_roll.STL"/>
      </geometry>
      <material name="">
        <color rgba="1 1 1 1"/>
      </material>
    </visual>
  </link>
  <joint name="r_arm_roll" type="continuous">
    <origin rpy="0 0 0" xyz="0 0 0"/>
    <parent link="r_arm_pitch"/>
    <child link="r_arm_roll"/>
    <axis xyz="1 0 0"/>
    <limit effort="100" lower="-1.57" upper="1.57" velocity="35"/>
  </joint>
  <transmission type="SimpleTransmission">
    <joint name="r_arm_roll"/>
    <actuator name="r_arm_roll_motor"/>
  </transmission>
  <link name="r_arm_yaw">
    <inertial>
      <origin rpy="0 0 0" xyz="-4.82749435400213E-05 -0.0052581506278393 -0.128821944854617"/>
      <mass value="1.120632"/>
      <inertia ixx="7.00575957554697E-05" ixy="-6.81658260938682E-10" ixz="-2.69427064597612E-10" iyy="8.53612265336775E-05" iyz="-6.95899873075696E-06" izz="8.82223899453284E-05"/>
    </inertial>
    <visual>
      <origin rpy="0 0 0" xyz="0 0 0"/>
      <geometry>
        <mesh filename="../../meshes/r_arm_yaw.STL"/>
      </geometry>
      <material name="">
        <color rgba="1 1 1 1"/>
      </material>
    </visual>
  </link>
  <joint name="r_arm_yaw" type="continuous">
    <origin rpy="0 0 0" xyz="0 0 0"/>
    <parent link="r_arm_roll"/>
    <child link="r_arm_yaw"/>
    <axis xyz="0 0 1"/>
    <limit effort="100" lower="-1.57" upper="1.57" velocity="35"/>
  </joint>
  <transmission type="SimpleTransmission">
    <joint name="r_arm_yaw"/>
    <actuator name="r_arm_yaw_motor"/>
  </transmission>
  <link name="r_forearm_pitch">
    <inertial>
      <origin rpy="0 0 0" xyz="-0.000127232990745116 -0.00951602649232586 -0.0522687552263488"/>
      <mass value="0.395825"/>
      <inertia ixx="9.55808447606916E-05" ixy="-4.53863489774233E-08" ixz="-5.41060583443891E-08" iyy="0.000126326373178394" iyz="9.40982665987077E-06" izz="0.00012103247488424"/>
    </inertial>
    <visual>
      <origin rpy="0 0 0" xyz="0 0 0"/>
      <geometry>
        <mesh filename="../../meshes/r_forearm_pitch.STL"/>
      </geometry>
      <material name="">
        <color rgba="1 1 1 1"/>
      </material>
    </visual>
  </link>
  <joint name="r_forearm_pitch" type="continuous">
    <origin rpy="0 0 0" xyz="0 0 -0.1636"/>
    <parent link="r_arm_yaw"/>
    <child link="r_forearm_pitch"/>
    <axis xyz="0 1 0"/>
    <limit effort="100" lower="-1.57" upper="1.57" velocity="35"/>
  </joint>
  <transmission type="SimpleTransmission">
    <joint name="r_forearm_pitch"/>
    <actuator name="r_forearm_pitch_motor"/>
  </transmission>
  <link name="r_hand_yaw">
    <inertial>
      <origin rpy="0 0 0" xyz="-0.000113133331993445 -0.0097448351680483 0.0817960724173413"/>
      <mass value="0.380792"/>
      <inertia ixx="7.64923982725728E-05" ixy="8.51115986496426E-09" ixz="1.40703608309957E-08" iyy="0.000122231132626729" iyz="-1.11226978982942E-06" izz="8.44935061081861E-05"/>
    </inertial>
    <visual>
      <origin rpy="0 0 0" xyz="0 0 0"/>
      <geometry>
        <mesh filename="../../meshes/r_hand_yaw.STL"/>
      </geometry>
      <material name="">
        <color rgba="1 1 1 1"/>
      </material>
    </visual>
  </link>
  <joint name="r_hand_yaw" type="continuous">
    <origin rpy="0 0 0" xyz="0 0 -0.191050000125729"/>
    <parent link="r_forearm_pitch"/>
    <child link="r_hand_yaw"/>
    <axis xyz="0 0 1"/>
    <limit effort="100" lower="-1.57" upper="1.57" velocity="35"/>
  </joint>
  <transmission type="SimpleTransmission">
    <joint name="r_hand_yaw"/>
    <actuator name="r_hand_yaw_motor"/>
  </transmission>
  <link name="r_hand_pitch">
    <inertial>
      <origin rpy="0 0 0" xyz="0.00735986990228184 -0.0047523802551166 0.00605888061339196"/>
      <mass value="0.376651"/>
      <inertia ixx="4.77321358097824E-05" ixy="-2.99709432812988E-06" ixz="4.71488437974188E-06" iyy="3.42470226388499E-05" iyz="4.61094199971347E-06" izz="2.51299600072388E-05"/>
    </inertial>
    <visual>
      <origin rpy="0 0 0" xyz="0 0 0"/>
      <geometry>
        <mesh filename="../../meshes/r_hand_pitch.STL"/>
      </geometry>
      <material name="">
        <color rgba="1 1 1 1"/>
      </material>
    </visual>
  </link>
  <joint name="r_hand_pitch" type="continuous">
    <origin rpy="0 0 0" xyz="0 0 0"/>
    <parent link="r_hand_yaw"/>
    <child link="r_hand_pitch"/>
    <axis xyz="0 1 0"/>
    <limit effort="100" lower="-1.57" upper="1.57" velocity="35"/>
  </joint>
  <transmission type="SimpleTransmission">
    <joint name="r_hand_pitch"/>
    <actuator name="r_hand_pitch_motor"/>
  </transmission>
  <link name="r_hand_roll">
    <inertial>
      <origin rpy="0 0 0" xyz="0.0045944493552252 -0.00586927010446042 -0.0836324643988434"/>
      <mass value="0.704669"/>
      <inertia ixx="0.000160651543151659" ixy="-5.37963063503334E-07" ixz="-9.47669219939636E-06" iyy="0.000229393712149694" iyz="-2.08351527945055E-05" izz="0.000219277776699058"/>
    </inertial>
    <visual>
      <origin rpy="0 0 0" xyz="0 0 0"/>
      <geometry>
        <mesh filename="../../meshes/r_hand_roll.STL"/>
      </geometry>
      <material name="">
        <color rgba="1 1 1 1"/>
      </material>
    </visual>
  </link>
  <joint name="r_hand_roll" type="continuous">
    <origin rpy="0 0 0" xyz="0 0 0"/>
    <parent link="r_hand_pitch"/>
    <child link="r_hand_roll"/>
    <axis xyz="1 0 0"/>
    <limit effort="100" lower="-1.57" upper="1.57" velocity="35"/>
  </joint>
  <transmission type="SimpleTransmission">
    <joint name="r_hand_roll"/>
    <actuator name="r_hand_roll_motor"/>
  </transmission>
  <!-- end frame -->
  <!-- <frame link="l_hand_pitch" name="l_hand_sole" xyz="0 0 -0.1" /> -->
  <!-- end frame -->
  <!-- <frame link="r_hand_pitch" name="r_hand_sole" xyz="0 0 -0.1" /> -->
</robot>

